<?xml version="1.0"?>
<robot name="horizontal_flap">
  <!-- Vertical bar (base) -->
  <link name="vertical_bar">
    <visual>
      <origin xyz="0 0 0.1" rpy="0 0 0"/>
      <geometry>
        <cylinder radius="0.005" length="0.2"/>
      </geometry>
      <material name="gray">
        <color rgba="1 1 1 1"/>
      </material>
    </visual>
    <collision>
      <origin xyz="0 0 0.1" rpy="0 0 0"/>
      <geometry>
        <cylinder radius="0.005" length="0.2"/>
      </geometry>
    </collision>
    <inertial>
      <mass value="0.001"/>
      <origin xyz="0 0 0" rpy="0 0 0"/>
      <inertia 
         ixx="0.0001" ixy="0" ixz="0"
         iyy="0.0001" iyz="0"
         izz="0.0001"/>
    </inertial>
  </link>
    

  <!-- Horizontal flap -->
  <link name="horizontal_flap">
    <visual>
      <origin xyz="0 0 0" rpy="0 0 0"/>
      <geometry>
        <box size="0.2 0.1 0.016"/>
      </geometry>
      <material name="box_color_horizontal_flap">
        <color rgba="1 1 0.5 1"/>
      </material>
    </visual>
    <collision>
      <origin xyz="0 0 0" rpy="0 0 0"/>
      <geometry>
        <box size="0.2 0.1 0.016"/>
      </geometry>
    </collision>
    <inertial>
      <mass value="0.001"/>
      <origin xyz="0 0 0" rpy="0 0 0"/>
      <inertia
         ixx="0.0001" ixy="0" ixz="0"
         iyy="0.0001" iyz="0"
         izz="0.0001"/>
    </inertial>
  </link>
    
  <joint name="flap_hinge_joint" type="continuous">
    <parent link="vertical_bar"/>
    <child link="horizontal_flap"/>
    <origin xyz="0 0 0.15000000000000002" rpy="1.5707963267948966 0 0"/>
    <axis xyz="0 1 0"/>
    <dynamics damping="0.0001" friction="0.0001"/>
    <limit lower="-3.141592653589793" upper="3.141592653589793"/>
  </joint>
    

</robot>
